from django import forms
from django.contrib.auth.models import User
from django.core.exceptions import ValidationError


class UserCreationForm(forms.Form):
    username = forms.CharField(max_length=100, label='Username', required=True)
    password = forms.CharField(max_length=100, label='Password', required=True,
                               widget=forms.PasswordInput)
    password_confirm = forms.CharField(max_length=100, label='Password Confirm', required=True,
                                       widget=forms.PasswordInput)

    def clean_username(self):
        username = self.cleaned_data.get('username')
        try:
            User.objects.get(username=username)
            raise ValidationError('User with this username already exists',
                                  code='username_exists')
        except User.DoesNotExist:
            return username

    def clean(self):
        super().clean()
        password_1 = self.cleaned_data['password']
        password_2 = self.cleaned_data['password_confirm']
        if password_1 != password_2:
            raise ValidationError('Passwords do not match',
                                  code='passwords_do_not_match')
        return self.cleaned_data
